<?xml version="1.0" ?>
<robot xmlns:xacro="http://www.ros.org/wiki/xacro">

<xacro:macro
	name="roller_macro"
	params="parent name xyz rpy">

		<link name="roller2_${name}_rim2_${parent}_link">
			<inertial>
				<mass value="0.00113845"/>
				<inertia
					ixx="2.53776e-08"
					ixy="0"
					ixz="0"
					iyy="2.53776e-08"
					iyz="0"
					izz="1.47666e-08"/>
			</inertial>
			<visual>
				<geometry>
					<mesh filename="package://open_base/mesh/roller.stl"/>
				</geometry>
				<material name="roller2_material">
					<color rgba="0.1 0.1 0.1 1"/>
				</material>
			</visual>
			<collision>
				<geometry>
					<mesh filename="package://open_base/mesh/roller.stl"/>
				</geometry>
			</collision>
		</link>
	<gazebo reference="roller2_${name}_rim2_${parent}_link">
    		<material>Gazebo/Black</material>
  	</gazebo>
		<joint name="roller2_${name}_rim2_${parent}_joint" type="continuous">
			<parent link="rim2_${parent}_link"/>
			<child link="roller2_${name}_rim2_${parent}_link"/>
			<axis xyz="0 0 1"/>
			<origin xyz="${xyz}" rpy="${rpy}"/>

		</joint>
	</xacro:macro>

</robot>
